# @exception break statement outside of loop

func foo(bar) {
  if bar == 2 {
    break
  }
}

for i = 1, i < 10 {
  foo(i)
}
